Workbook

Sheet combined_output_id (3)
A1: Column1 | B1: int_legacyid | C1: st_description | D1: y_pred | E1: Confidence Level | F1: Coluna1 | G1: Coluna2
A2: 0 | B2: 133503775 | C2: No dia 24/11, fiz uma compra de dois aspiradores de pó robô, número do pedido 27129081, onde estavam em promoção com 50% de desconto, recebi o e-mail do Kabum confirmando a compra e a pre-autorização do pagamento, e um SMS da operado do meu cartão confirmando compra aprovada. <br />Porém coisa de mais ou menos uma hora depois, recebo um e-mail informado que a compra foi cancelada por divergência com o cartão de crédito. <br />Hoje pela manhã, entrei em contato com a operadora do meu cartão, e me informaram que está tudo ok com a compra, que não houve nenhuma recusa por parte da operadora, autorização número 671040. <br />Liguei para o SAC, afim de tentar entender o que aconteceu e corrigir para manter a compra, fui informado que o sistema pode cancelar a compra se tiver alguma informação errada, porém eles não podem me passar qual a informação foi errada, e que eu deveria verificar junto a operadora do cartão, informei que já tinha confirmado e que estava tudo ok com o cartão, então a atendente me passou mais umas 5 vezes que o sistema faz isso para proteger o cliente, e pode cancelar por motivos divergentes, quando questionei se conseguiria manter a compra alterando a forma de pagamento, me informou que o pedido já estava cancelado e não teria nada o que fazer, ao questionar se eu estava em contato mesmo com o SAC, e se teria como fazer uma reclamação pois realmente tenho interesse em manter a compra, fui informado que como o pedido consta cancelado não tem o que fazer, apenas fazendo uma nova compra, onde o dobrou o valor do produto.<br /><br />A sensação que dá é que a Kabum se arrependeu de vender o produto nesse valor, onde cancelou o pedido apenas para conseguir vender as unidades pelo dobro do preço. <br /><br />Gostaria que a Kabum honre com sua palavra e finalize a venda conforme foi feita. Pois a compra seria presente de Natal para minha mãe, e agora ela ficará esperando.<br /> | D2: blackfriday | E2: 99 | F2: =combined_output_id__3[[#This Row],[y_pred]] -> blackfriday | G2: =IF(combined_output_id__3[[#This Row],[y_pred]]=combined_output_id__3[[#This Row],[Coluna1]],1,0) -> 1
A3: 1 | B3: 133555945 | C3: Comprei uma televisão o KabuM e realmente foi um Bum! O produto foi entregue na ultima 2 feira 22.11 com a tela toda quebrada. No próprio dia entrei em contato com eles, abri uma reclamação no SAC e fotografei o produto e a embalagem, conforme orientação.<br />No dia seguinte 23.11 retornaram o email informando que iriam verificar o ocorrido com o time de transportes e em alguns dias teria um retorno com novas instruções. &quot;Se comprei do KabuM que culpa tenho e porque preciso aguardar eles verificarem com o time de transportes?&quot;<br />24.11 fui informado que encaminharam meu chamado &quot;pedido de troca do produto&quot; para área responsável e solicitada a coleta do produto junto a transportadora, pediram para que eu confirmasse meu endereço e todos os dados para retirada do produto.<br />25.11, entrei em contato pelo telefone pois passadas 24horas do ultimo contato por email não obtive retorno e para minha surpresa, solicitaram todas as informações novamente. Informaram que não possuem data para retirada do produto e somente após retirada do produto e analise, poderão se posicionar quanto ao envio de outra televisão.<br />Infelizmente esta empresa ainda não está preparada para atender o consumidor, pois a mesma esta duvidando da palavra que o produto chegou quebrado, quer analisar para se posicionar. Pior, não sabem quando a transportadora poderá retirar o produto, que esta disponível deste 22.11 e muito menos quando irão entregar o novo produto. Aonde está o respeito com o consumidor?????? O Produto está pago e minha parte está cumprida, so falta o produto que adquiri.<br />Não comprem nesta empresa, pois se tiveram problema, não tem o menor respeito pelo consumidor... | D3: Não | E3: 98 | F3: =combined_output_id__3[[#This Row],[y_pred]] -> Não | G3: =IF(combined_output_id__3[[#This Row],[y_pred]]=combined_output_id__3[[#This Row],[Coluna1]],1,0) -> 1
A4: 2 | B4: 133537001 | C4: Dia 24/11 ( Ontem ) através da plataforma de buscas do Google procurando um novo monitor, vi a oferta que apareceu na Kabum do Monitor Asus ProArt 34. Como me interessou e pela confiança e anos de mercado da empresa, não tive o temor de gerar o pagamento via pix, e de imediato, efetuar o pagamento. <br /><br />Pois bem, 1 dia depois eu recebo a Nota fiscal do produto e nela consta: Monitor Asus Gamer 27 polegadas, que com exceção da marca do produto, em nada tem a ver com o produto que anteriormente havia comprado.<br /><br /><br />A kabum está me enviando um produto diferente daquele que eu comprei <br /><br />.<br /><br />Conforme print em anexo, eu efetuei a compra do produto: <br /><br /><br />Monitor Profissional Asus ProArt IPS 4k<br /><br />.<br /><br />Porém, a nota gerada foi referente ao Monitor Gamer Asus 27 165hz.<br /><br />.<br /><br />Gostaria de saber como iremos resolver isto, visto que desejo receber o produto que comprei no ato do pagamento. <br /><br /><br />Obrigado<br /><br /> | D4: Não | E4: 96 | F4: =combined_output_id__3[[#This Row],[y_pred]] -> Não | G4: =IF(combined_output_id__3[[#This Row],[y_pred]]=combined_output_id__3[[#This Row],[Coluna1]],1,0) -> 1
A5: 3 | B5: 133509813 | C5: comprei um notbook chego dia 24/11/2021 e abri protocolo para devolver dia 25/11/2021 e a kabum me iguinoro fechando o protocolo de arrependimento testei e nao gostei e nem tirei os plastiquinhos que vem grudado no notbook protocolo 2516438211125 gmail cadastrado na kabum lib****08@gmail.com quero que voces aceite a devoluçao e devolva o valor pago na mesma conta corrente em que paguei por pix se tiverem que falar com migo eu respondo por gmail e whatsapp | D5: Não | E5: 99 | F5: =combined_output_id__3[[#This Row],[y_pred]] -> Não | G5: =IF(combined_output_id__3[[#This Row],[y_pred]]=combined_output_id__3[[#This Row],[Coluna1]],1,0) -> 1
A6: 4 | B6: 133488705 | C6: Fiz a compra no dia 21-11-2021 de um jogo ( Ghost of Tsushima ) no valor de 99 reais.<br />Recebi uma mensagem e e-mail , dizendo que a minha compra não foi autorizada , pois precisa de uma liberação do banco.<br />Meu cartão tem limite , e engraçado , que o jogo que estava 99 reais foi para 175.<br />Meu banco não precisa de liberação , e agora , fico recebendo mensagem dizendo que será feita uma nova tentativa em duas horas pra realizar uma nova cobrança. Por sinal , já comprei uma TV , com uma valor muito maior e não precisou nada disso! <br />Acredito que seja pela mudança do preço , e quem tem que arcar com isso sou eu !<br /><br />Só para constar, fiz uma compra no mesmo dia , em outro site, com um valor bem maior e não pediu nada, como não pedem a mais de 4 anos que tenho esse cartão<br /><br />Entrei em contato por e-mail , e só me mandavam frases automáticas, &quot;desculpe pelo transtorno&quot;<br />E falaram que só pode alterar o cartão depois de 48 horas, mas fui informado depois de muito tempo, ai é complicado<br />Solicitei até o desconto, pois o erro não foi meu, meu cartão está ok, tudo certo, e que eu não poderia arcar com essa alteração, pois eu queria com o valor menor.<br /><br />Entrei em contato com meu banco, tenho protocolo e tudo, resumindo : Tenho limite, não preciso de liberação para compra ( se não pede para uma compra de 2 mil, não vai pedir para de 99 )<br />Exijo uma posição o mais breve possível , pois isso se categoriza como prática abusiva .<br /><br /><br /><br />Essa é a minha última tentativa antes de levar para uma outra esfera.<br /><br />Número do pedido 27057409 - | D6: Não | E6: 70 | F6: =combined_output_id__3[[#This Row],[y_pred]] -> Não | G6: =IF(combined_output_id__3[[#This Row],[y_pred]]=combined_output_id__3[[#This Row],[Coluna1]],1,0) -> 1
A7: 5 | B7: 133453477 | C7: ESTOU HÁ 2 DIAS TENTANDO DEVOLVER UM FONE BLUETOOTH (QUE SÓ FUNCIONA UM LADO, O OUTRO SO ESQUENTA E NÃO LIGA) PRA SER ESTORNADO E NÃO CONSIGO. PEDIDO N#26741782, SIMPLESMENTE FICA EM ANÁLISE E NÃO PROCEDE. É MUITO TRÂMITE PRA UMA SIMPLES DEVOLUÇÃO. FAZEM DE FORMA PROPOSITAL PARA QUE SEJA DIFÍCIL ESSA PROCESSO E AINDA DENTRO DO PRAZO DE 7 DIAS, O QUE É GARANTIDO EM LEI. Art. 49 do CDC. | D7: Não | E7: 99 | F7: =combined_output_id__3[[#This Row],[y_pred]] -> Não | G7: =IF(combined_output_id__3[[#This Row],[y_pred]]=combined_output_id__3[[#This Row],[Coluna1]],1,0) -> 1
A8: 6 | B8: 133521863 | C8: Comprei vários gift cards de Ps em diferentes pedidos, seguem os números: #27072722 #27072648 #27072574 #27072537 #27072498 #27072441 #27072389 #27072340 #27070283<br /><br />Fiz a compra no dia 22/11 e no dia seguinte o site informa que foi entregue. Verifiquei meu email, minha caixa de spam e NÃO RECEBI NENHUM DOS ITENS.<br /><br />Entrei em contato com a empresa no dia 25/11 em torno de 12:00 e fui extremamente mal atendido pela Sra. Caroline. Arrogante e mal educada, disse que não poderia resolver meu problema e me mandou mandar email pro atendimento. se fosse pra fazer isso eu não teria entrado em chat.. Inacreditável!<br /><br />QUERO COM URGÊNCIA RECEBER OS CÓDIGOS DOS GIFT CARDS QUE COMPREI!<br /> | D8: Não | E8: 99 | F8: =combined_output_id__3[[#This Row],[y_pred]] -> Não | G8: =IF(combined_output_id__3[[#This Row],[y_pred]]=combined_output_id__3[[#This Row],[Coluna1]],1,0) -> 1
A9: 7 | B9: 133507449 | C9: Por diversas vezes já comprei com a Kabum e não tive nenhum tipo de problema, agora recentemente estou tentando comprar uma TV (samsung qled a60) conforme promoção da Black November no valor 2.999,90 + frete, e por duas vezes recusaram minha compra, na primeira recusa entrei em contato via telefone com a Kabum, falei com o atendente Maick, 24/11/2021 as 15:30, o mesmo me informou que foi por divergência de dados que a compra foi cancelada porem não tinha a informação de qual seria essa divergência, revemos todos os dados juntos e na conversa informei que o cartão de credito usado na compra era em nome da minha esposa, o atendente informou que poderia ser esse motivo da divergência (nunca tinha ouvido falar disso), então, efetuei novamente a compra pelo login dela após ter feito uma revisão antes no cadastro em todos os dados dela para não corremos risco de perdemos a compra e por fim a promoção..<br />E novamente depois de algumas horas, pedido cancelado novamente, as duas vezes a compra foi confirma pelo cartão normalmente;<br /><br />Na minha opinião trata-se de uma propagando enganosa a qual a Kabum não está vendendo o produto pelo valor indicado na promoção e usando isso em forma de estratégia para chamar atenção do consumidor, pois tenho certeza que se eu efetuar a compra da TV agora com + de 2000,00 reais mais caro a compra vai ser efetivada até o fim.<br /><br />22/11/2021 1 tentativa de compra : N PEDIDO 27086378<br />24/11/2021 - 2 tentativa de compra : N PEDIDO 27119569<br /><br /><br />Obs: O credito da 1 compra ja foi estornado, aguardo o estorno da 2 compra.<br /><br />E exerço meu direito legal de consumidor, solicitando que habilite minha compra no preço promocional que foi anunciado antes do cancelamento da compra.<br /><br />Tenho todos os prints do site e do cartão referente as compras.<br /><br />Aguardo retorno. | D9: blackfriday | E9: 99 | F9: =combined_output_id__3[[#This Row],[y_pred]] -> blackfriday | G9: =IF(combined_output_id__3[[#This Row],[y_pred]]=combined_output_id__3[[#This Row],[Coluna1]],1,0) -> 1
A10: 8 | B10: 133465791 | C10: Comprei o produto no site dia 16. Após o produto sair para entrega, houve comunicação de extravio no dia 19. <br /><br />Desde então, após muito reclamar, geraram um novo pedido &quot;fantasma&quot; na plataforma. Porém não geram nova NF, não entregam novo produto à transportadora e a única comunicação que eu recebo é a de que preciso esperar. Sem um SLA, um novo prazo ou qualquer outro tipo de informação além de: Espere..<br /><br /> | D10: Não | E10: 99 | F10: =combined_output_id__3[[#This Row],[y_pred]] -> Não | G10: =IF(combined_output_id__3[[#This Row],[y_pred]]=combined_output_id__3[[#This Row],[Coluna1]],1,0) -> 1
A11: 9 | B11: 133569523 | C11: Recebi um e-mail dizendo que minha encomenda saiu pra entrega ontem as 16:20. Fiquei horas e horas aguardando e nada.<br />Hj já é dia 26 e gostaria de saber aonde tá o entregador com a minha encomenda?<br /><br />Ele tá fazendo entregas a pé? Pq não justifica a demora pra entregar ja que ele se encontra em rota de entrega. Preciso de um parecer ou vou cancelar a compra.<br /><br /> | D11: blackfriday | E11: 96 | F11: Não | G11: =IF(combined_output_id__3[[#This Row],[y_pred]]=combined_output_id__3[[#This Row],[Coluna1]],1,0) -> 0
A12: 10 | B12: 133549919 | C12: Fiz uma compra de uma tv, sem nenhuma explicação eles cancelaram minha compra porém mesmo assim foi debitado no cartão! Vou ter que pagar uma parcela enorme sem ter nenhum produto ! Nunca vi isso ! | D12: Não | E12: 95 | F12: =combined_output_id__3[[#This Row],[y_pred]] -> Não | G12: =IF(combined_output_id__3[[#This Row],[y_pred]]=combined_output_id__3[[#This Row],[Coluna1]],1,0) -> 1
A13: 11 | B13: 133547109 | C13: Meu nome é José Maria e comprei pelo aplicativo da Kabum, em 20 de novembro de 2021, uma cadeira CADEIRA GAMER HUSKY GAMING STORM, por conta do preço competitivo.<br />Depois de completada a compra, recebi um e-mail da Kabum, informando que deveria entrar em contato com a operadora de meu cartão de crédito, para que a compra fosse aprovada.<br />Uma hora depois, entrei em contato com a Ourocard Visa, a qual ratificou que a compra deveria ser aprovada, sim, uma vez que a Kabum TEM RESTRIÇÕES DE PAGAMENTO COM A OPERADORA. a VISA ne informou que deveria refazer a operação.<br />Fui, novamente, ao aplicativo e tive de fazer uma nova compra, uma vez que não havia a opção refazer o pedido. Em seguida, remeti um e-mail para o faleconosco@kabum.com.br, solicitando que cancelasse o primeiro pedido. <br />Em torno de três horas depois, percebi que um novo débito pela Kabum, havia sido feito em meu cartão de crédito. Tentei fazer um contato pelo chat e não consegui. Tentei o telefone do SAC (19) 2114.4444 e também não consegui, mesmo sendo sábado às 18h, ainda dentro do horário de atendimento, que é previsto até às 20h, conforme está no site. <br />Restou-me, encaminhar um novo e-mail ao faleconosco@kabum.com.br, mais uma vez esclarecendo e solicitando o cancelamento do valor relativo à segunda compra efetuada.<br />Logo no dia útil seguinte, na segunda dia 22 de novembro, recebi por volta das 07h20, um e-mail da Kabum, informando que o pedido indevido acabava de ser separado para se encaminhado.<br />Liguei ao SAC às 08h23 e o atendente Miguel recebeu meus esclarecimentos e solicitação de estorno da compra indevida. Ele me informou que não poderia cancelar o pedido, uma vez que, automaticamente e no sábado, já havia sido despachado, mesmo tendo encaminhado o meu e-mail ao faleconosco@kabum.com.br.<br />Informou que o procedimento seria não receber o produto na entrega e que, aí sim, eu teria meu estorno. Não me deu nenhum número de protocolo, uma vez que a Kabum não registra atendimentos por meio de protocolos, conforme o Miguel me informou.<br />Mais uma vez, remeti um novo e-mail faleconosco@kabum.com.br, novamente sem qualquer resposta (ainda não me responderam nada e o e-mail não retornou como inválido). <br />Por fim, acabei recebendo as duas cadeiras e não responderam minhas solicitações por e-mail. Tomei a decisão de receber as duas cadeiras POR NÃO ACREDITAR que a Kabum me estornaria, ou seja, medo de devolver o produto e a loja não fazer o estorno. <br />Cabe ressaltar que nunca vi esse tipo de procedimento. Normalmente, há a possibilidade de estono na maioria dos estabelecimentos, quando solicitado imediatamente, o que não ocorreu de forma alguma com a Kabum.<br />No aplicativo, há até a opção de arrependimento da compra, que não funciona. Não consigo, nem mesmo, fazer uma avaliação do produto, nem no aplicativo e nem no site.<br />Ou seja, COMPREI UM PRODUTO QUE NÃO QUIS. Fiz reclamações diversas em tempo mínimo e não recebi qualquer resposta ou atenção por parte da Kabum, o que me leva a NUNCA MAIS COMPRAR OU CONFIAR NA KABUM. | D13: blackfriday | E13: 99 | F13: Não | G13: =IF(combined_output_id__3[[#This Row],[y_pred]]=combined_output_id__3[[#This Row],[Coluna1]],1,0) -> 0
A14: 12 | B14: 133468697 | C14: Adquiri um monitor em 16/11/2021 com entrega prevista para dia 22/11/2021. Não houve entrega dia 22/11/2021 e ontem o sistema da Sequoia, parceira da Kabum acusou que o produto tinha saído para entrega. Como moro em um prédio com portaria estava ansioso pois sabia que o produto teria chegado e estaria na portaria. Pois bem, não chegou e para minha surpresa o sistema da Sequoia atualizou para DESTINATÁRIO AUSENTE.<br /><br />Entrei em contato agora com o chat da Kabum! para tentar uma solução ou cancelar a compra, não consegui. Ou seja, não sei quando o produto vai chegar, se é que vai chegar e paguei 42 reais de frete para ser feito de palhaço! | D14: blackfriday | E14: 85 | F14: Não | G14: =IF(combined_output_id__3[[#This Row],[y_pred]]=combined_output_id__3[[#This Row],[Coluna1]],1,0) -> 0
A15: 13 | B15: 133453003 | C15: no cadastro do meu pai tentei comprar 1 tv e fiz a operação 3 vezes pois a operação anterior sempre era cancelada, desconheço os motivos.. acontece que o limite do meu cartão foi todo comprometido como se tivesse efetuado as operações e não foi completado nada! liguei na operadora do cartão e os mesmos disseram que a kabum deve efetuar o estorno ( de uma compra que nao foi nem feita, so estão segurando meu limite)<br />KABUM, preciso usar meu cartão para compras de casa, necessidades urgentes! Um absurdo voces segurarem o limite do meu cartão sendo que nao existe a compra!!!!!!! ja liguei e pedi cancelamento e estorno, e voces estão dificultanto e muito esse processo!<br />Estou totalmente decepcionada com a forma de trabalho da kabum! | D15: blackfriday | E15: 97 | F15: =combined_output_id__3[[#This Row],[y_pred]] -> blackfriday | G15: =IF(combined_output_id__3[[#This Row],[y_pred]]=combined_output_id__3[[#This Row],[Coluna1]],1,0) -> 1
A16: 14 | B16: 133502579 | C16: Faltavam 4h para terminar uma oferta de aspirador de pó, da marca própria, e no site dizia haver 60 unidades disponíveis. Foi negada a compra dizendo que digitei errado o código verificador. Refiz a compra, com outro cartão, e dessa vez dizia haver ainda 26 unidades do produto. A operadora chegou a confirmar que o cartão tinha limite e estava ativo, mas novamente a compra foi negada no site dizendo que novamente eu errei o código verificador. Como pode a operadora confirmar que o cartão está ativo e tem limite disponível e o site &quot;inventar&quot; que eu digitei algo errado? Se não vão manter a oferta, tirem do site. Fingir erro do cliente pra não cumprir a oferta é sacanagem.. | D16: blackfriday | E16: 56 | F16: =combined_output_id__3[[#This Row],[y_pred]] -> blackfriday | G16: =IF(combined_output_id__3[[#This Row],[y_pred]]=combined_output_id__3[[#This Row],[Coluna1]],1,0) -> 1
A17: 15 | B17: 133467979 | C17: Hoje fiz uma compra de um monitor que no anuncio tinha senguinte descriçao.<br />Monitor Profissional Asus ProArt 34 IPS, 4K UHD, HDR 400, 100% sRGB, Calman Certified, HDMI/DisplayPort/USB-C, Ajuste de Altura - PA329CV.Por ser um monitor que atendia a minha necessidade eu comprei no pix.Mas horas apos o anuncio mudou.Monitor Gamer Asus 27 LED, Wide, 165 Hz, Full HD, 0.5ms, Adaptive Sync, HDMI/DisplayPort, Ajuste de Altura, Vesa, Som Integrado - VG278QR.E esse monitor nao atende minhas necessidade,gostaria de saber como podemos resolver isto. | D17: Não | E17: 68 | F17: blackfriday | G17: =IF(combined_output_id__3[[#This Row],[y_pred]]=combined_output_id__3[[#This Row],[Coluna1]],1,0) -> 0
A18: 16 | B18: 133522087 | D18: Não | E18: 85 | F18: =combined_output_id__3[[#This Row],[y_pred]] -> Não | G18: =IF(combined_output_id__3[[#This Row],[y_pred]]=combined_output_id__3[[#This Row],[Coluna1]],1,0) -> 1
A19: 17 | B19: 133515859 | C19: Comprei um produto na kabum que está demorando pra atualizar o status. <br />E também queria saber oque significa esse status atual do produto?<br />Pedido 27113448 | D19: Não | E19: 66 | F19: =combined_output_id__3[[#This Row],[y_pred]] -> Não | G19: =IF(combined_output_id__3[[#This Row],[y_pred]]=combined_output_id__3[[#This Row],[Coluna1]],1,0) -> 1
A20: 18 | B20: 133517151 | C20: Comprei um SSD recentemente, selecionei o endereço que queria que fosse enviado, pagamento aprovado. Depois de dois dias recebo um email dizendo que o &quot;O sistema encontrou divergência no endereço cadastrado e endereço de entrega&quot; e pedia para retornar um email confirmando o endereço de entrega. O problema já começa aí, tu seleciona um endereço para entrega e depois de dois dias te mandam um email pedindo pra confirmar o endereço. Não bastando isso, no dia seguinte recebo um email dizendo que o &quot;Pedido estava aguardando retorno do cliente&quot;. Tento entrar em contato pelo chat, sem atendimento até agora. Que decadência. | D20: Não | E20: 75 | F20: =combined_output_id__3[[#This Row],[y_pred]] -> Não | G20: =IF(combined_output_id__3[[#This Row],[y_pred]]=combined_output_id__3[[#This Row],[Coluna1]],1,0) -> 1
A21: 19 | B21: 133547979 | C21: No dia 19 de Novembro de 2021, abri um protocolo de numero 2509015211119. Após alguns dias me pediram mais fotos do produto para analisar, no dia de hoje 25/11/2021 recebi que meu produto não iria ser trocado pois ele teve um defeito físico no produto, sendo que o produto ja veio desta forma, com marcas de amassado na caixa do produto (relatada por foto), o produto nunca foi utilizado e nem instalado. após a resposta negativa sobre a troca, entrei em contato com o chat da empresa pedindo melhores explicações e se teria alguma forme de eu responder esse protocolo pois ele foi encerrado pela loja, e o que foi me respondido é que eles não poderiam fazer nada. | D21: Não | E21: 96 | F21: =combined_output_id__3[[#This Row],[y_pred]] -> Não | G21: =IF(combined_output_id__3[[#This Row],[y_pred]]=combined_output_id__3[[#This Row],[Coluna1]],1,0) -> 1
A22: 20 | B22: 133501025 | C22: Fiz a compra de uma TV Sansung QLED na promoção pela conta do meu marido, usando meu cartão de crédito. O limite do meu cartão foi debitado, porém, a compra foi cancelada por divergência, por que o cartão não era no nome do meu marido (nunca vi isso na minha vida) mas tudo bem. Liguei na Kabum e fui informada que teria até 30 dias para o limite ser liberado na conta, como queriamos muito a TV com a promoção, usei todo o resto do meu limite e dessa vez fiz o pedido pelo meu login, todos meus dados corretos, o cartão em MEU NOME e novamente, limite usado, porém, compra cancelada! Resumindo, perdi a promoção, a TV aumentou 2 mil reais o preço e meu limite todo usado e não consigo comprar em outra loja KKKK Isso pra mim foi a maior falta de respeito que já sofri com alguma loja. Gostaria de uma posição da KABUM de pelomenos me ajudar a comprar a TV com a promoção, pq agora vou ser lesada. <br />NÚMERO DO PEDIDO: #27119569 | D22: blackfriday | E22: 61 | F22: =combined_output_id__3[[#This Row],[y_pred]] -> blackfriday | G22: =IF(combined_output_id__3[[#This Row],[y_pred]]=combined_output_id__3[[#This Row],[Coluna1]],1,0) -> 1
A23: 21 | B23: 133484979 | C23: Solicitei uma smart tv da LG no site aproveitando a promoção de blackfriday, num do meu pedido 27043285. Chegou até que bem rápido mas quando liguei já percebi que a tv estava com defeito. Ela fica muito lenta para qualquer função mesmo as que não utilizam internet, para o som do nada e de vez em quando fica preta, aí tento fazer qualquer função nela e não vai, até para desligar demora uns 10 segundos depois que eu apertei. Não consigo fazer a solicitação de arrependimento e devolução no site, tanto o site quanto o aplicativo simplesmente travam na hora de eu solicitar. Engraçado que para comprar ambos são super rápidos e práticos mas para solicitar uma troca resolvem trancar. Tive que solicitar essa troca manualmente pelo telefone da Kabum mas achei estranho que não tem nenhum número de protocolo. O atendente Luca me pediu para aguardar o prazo de até 3 dias para que me enviem e-mail pedindo as fotos da televisão e me orientando de como fazer a devolução para receber meu estorno. Estou muito triste pois vou acabar não conseguindo comprar outra televisão a tempo de promoções de blackfriday já que vai demorar todas essas transações para que eu finalmente consiga um estorno. Não tenho mais limite para comprar outra tv e ainda vou ter que acabar pagando a primeira parcela dessa tv que me foi entregue com defeito e me encontro aqui sem nenhum protocolo ou orientação de uma televisão que chegou hoje e não pude utilizar nenhum minuto. | D23: blackfriday | E23: 86 | F23: =combined_output_id__3[[#This Row],[y_pred]] -> blackfriday | G23: =IF(combined_output_id__3[[#This Row],[y_pred]]=combined_output_id__3[[#This Row],[Coluna1]],1,0) -> 1
A24: 22 | B24: 133536769 | C24: Boa tarde!<br /><br />No dia 23/11/21 comprei uma cadeira gamer na Kabum, porém desde a data não estão me dando o suporte com a atualização do pedido no site que não esta sendo feita até a data de hoje. <br /><br />venho através deste pedir auxilio com os mesmo e mostrar a indignação com o atendimento precário do estabelecimento no qual ao iniciar um chat para saber o que esta acontecendo e logo em seguida pediram uns dados não terminei nem de digitar meu nome e fecharam como se eu estivesse offline. | D24: Não | E24: 99 | F24: =combined_output_id__3[[#This Row],[y_pred]] -> Não | G24: =IF(combined_output_id__3[[#This Row],[y_pred]]=combined_output_id__3[[#This Row],[Coluna1]],1,0) -> 1
A25: 23 | B25: 133534221 | C25: Realizei um pedido no site do Kabum dia 23/11/2021 pedido (27089320), onde ficou em análise de aprovação. No dia seguindo o status do pedido estava como cancelado, porém, até o momentos o valor está descontado na minha fatura, ou seja , comprometeu um crédito de 2.100 reais. Um absurdo, nunca vi isso , cancela a compra e desconta o crédito da pessoa ??? Falta de respeito com os clientes, minha primeira e última compra no site, pois me prejudicou muito. Em contato com a central de atendimento me informaram que tem que esperar o fechamento da fatura. A questão é , como vou pode comprar o que eu queria sendo que a Kabum comprometeu meu crédito ??? Aguardo estorno URGENTE. | D25: blackfriday | E25: 98 | F25: Não | G25: =IF(combined_output_id__3[[#This Row],[y_pred]]=combined_output_id__3[[#This Row],[Coluna1]],1,0) -> 0
A26: 24 | B26: 133550929 | C26: Comprei um aspirador de pó robô em preço promocional no site da Kabum no dia 23/11/21 no cartão de crédito. O mesmo já foi lançado no extrato de pagamentos do cartão. porém sem um motivo plausível cancelaram minha compra alegando divergência de informações. Recebi um e-mail tempos depois da realização da compra informando que os dados do cartão e os dados cadastrais estão divergentes.o que não é verdade pois o cadastro no site é em meu nome com meu CPF assim como o cartão de crédito. Tentei entrar no chat mas fiquei horas esperando. e nenhum atendente me atendeu. Mandei um email para faleconosco@kabum.com.br e ainda não tive retorno. Espero resolver a situação por aqui visto que eu realizei a compra no período em que o produto estava disponível em um determinado valor e agora não consigo comprar novamente pois o preço aumentou. E não cabe simplesmente cancelar sem nenhum motivo cabível já que está tudo certo com meu cartão de crédito e dados cadastrais. Espero uma resposta por parte da empresa. | D26: blackfriday | E26: 99 | F26: Não | G26: =IF(combined_output_id__3[[#This Row],[y_pred]]=combined_output_id__3[[#This Row],[Coluna1]],1,0) -> 0
A27: 25 | B27: 133543747 | C27: Efetuei o cancelamento do pedido #27117757 e, por conta disso, tinha disponível um valor considerável na minha conta da KABUM para usar como crédito no site.<br />Hoje (25/11) apareceu uma oportunidade de compra de uma &quot;Placa de Vídeo Asus TUF NVIDIA GeForce GTX 1660 TI T6G Evo Gaming, 6GB GDDR6, NVIDIA Turing Architecture - 90YV0CT9-M0NA00&quot; no valor de R$ 3268 para quem é cliente prime.<br />Assim sendo, incluí no carrinho 2 placas e a assinatura prime.<br />O crédito disponível era mais que suficiente para efetuar a compra dos referidos produtos. Porém, na hora que eu colocava em &quot;finalizar a compra&quot;, eu era redirecionado para a tela anterior de selecionar o tipo de pagamento (só aparecia boleto no valor de R$ 0,00). Mesmo selecionando o boleto (única opção), eu ia para a tela seguinte de finalizar o pedido e, novamente, voltava para a tela anterior de selecionar o tipo de pagamento.<br />Entrei em contato via chat com a atendente Monique Isabel, dia 25 de Nov de 2021, às 14:19 relatando o problema e, após muita demora, às 14:40 ela mandou a seguinte mensagem: &quot;Entendi, tenta deslogar e logar no site novamente e refaça a compra.&quot;. No minuto seguinte, SAIU DA CONVERSA e me deixou sem nenhuma solução (prints em anexo).<br />Por conta desse problema técnico, o tempo foi passando, passando, passando, eu não tive a opção de efetuar o pagamento por outro meio que não fosse o crédito disponível e, no fim das contas, a oferta encerrou e não comprei.<br />Considerando, portanto, que possuo crédito em conta e que ainda possuo interesse no produto, peço que a KABUM entre em contato comigo para finalizar o pedido e cumprir com a oferta apresentada, nos termos do art. 35, I do CDC.<br />Obrigado | D27: blackfriday | E27: 99 | F27: =combined_output_id__3[[#This Row],[y_pred]] -> blackfriday | G27: =IF(combined_output_id__3[[#This Row],[y_pred]]=combined_output_id__3[[#This Row],[Coluna1]],1,0) -> 1
A28: 26 | B28: 133531285 | C28: Fiz uma compra no dia 24/11/2021, de um Ipad no valor aproximado de 8400 reais e aproveitei uma promoção do Santander onde dava 21% de cashback. A compra foi autorizada pelo banco (inclusive usou limite do meu cartão) mas foi cancelada pela Kabum sem nenhuma explicação.<br />Fiz a compra novamente no mesmo dia pra aproveitar a promoção do cashback (que só valia naquele dia) e desde então a compra está em análise.<br />O valor do Ipad agora é 12.000 reais e não tenho mais acesso a promoção de cashback.<br />Porque a Kabum cancelou a compra? Apenas pra eu não participar da promoção? Quando entrei em contato o atendende disse que não podia me falar o motivo do cancelamento | D28: blackfriday | E28: 99 | F28: =combined_output_id__3[[#This Row],[y_pred]] -> blackfriday | G28: =IF(combined_output_id__3[[#This Row],[y_pred]]=combined_output_id__3[[#This Row],[Coluna1]],1,0) -> 1
A29: 27 | B29: 133575167 | C29: No dia 23/11/2021 foi feito uma compra onde a mesma foi cancelada no dia pela loja, porém a transação ficou presa entre a empresa e o operadora.<br />Procurei auxilio lingando no suporte da empresa e a mesma só me informou que, a compra não foi capturada e não há como falar com o setor responsável (financeiro), sendo assim procurei a operadora do cartão, já estes me informaram que foi capturado sim e a transação está com a KABUM (inclusive me passaram o numero da transação). <br />O problema é, preciso comprar. O limite esta preso por essa compra cancelada sem ao menos contatar o cliente, e não tenho uma resposta resolutiva apenas aguarde, não posso esperar passar de hoje.<br />Como faço para liberar o limite que esta preso? | D29: Não | E29: 75 | F29: =combined_output_id__3[[#This Row],[y_pred]] -> Não | G29: =IF(combined_output_id__3[[#This Row],[y_pred]]=combined_output_id__3[[#This Row],[Coluna1]],1,0) -> 1
A30: 28 | B30: 133481597 | C30: No dia 23/11/21 eu estava a procurar uma cadeira gamer de melhor qualidade para meus 2 filhos na internet e numa página tinha uma propaganda de uma cadeira Husky e me chamou a atenção pelo alto valor de R$849,95 e pensei, &quot;meu deus, deve ser um modelo novo por este preço&quot; pois as 2 últimas que adquiri no Kabum da marca Husky modelo Snow não duraram nada inclusive sendo trocado uma delas o assento e logo depois o encosto e logo que venceu a garantia não dava mais para sentar nelas pois a espuma sumiu de tão vagabunda que é e no site diz &quot;&quot;&quot; espuma de alta qualidade&quot;&quot;, &quot;&quot;&quot;aguenta 130kg&quot;&quot;imagina se não fosse de qualidade e não aguentasse o peso informado, meus filhos pesam 80kg um e o outro 69kg. Inclusive antes de jogar fora só para constar, eu tirei todo couro PU que é vagabundo e resseca logo no primeiro ano para ver a tal espuma de qualidade e adivinhem amigos consumidores, a espuma é refugo de sobras picotadas, são flocos de sobra de todo tipo de cor e tamanho prensada formando o acento. É o pior tipo de espuma que existe pois é resto de espumas e o assento é de compensado fraco prensado em laminas. O preço a 30 dias atrás estava igual as outras cores mas quando vi que apenas pela cor estão cobrando R$894,70 ou um baita desconto a vista por R$849,95 me revoltei, pois eu não gostaria de ser enganado também. Este Kabum é uma piada. Antes da Black subiram uma cadeira simplesmente pela cor? Custava R$499,00 / 509,00. Fiquei furioso por estarem a enganar um futuro comprador cobrando quase R$900,00 por uma cadeira comum. Eu já estava furioso com esta loja por isso, aí para minha surpresa estou passando numa avenida aqui da minha cidade no dia de hoje 24/12 onde tem várias lojas de móveis para escritório e eu vi a mesma cadeira, exatamente igual a esta do Kabum, o mesmo courino PU, a mesma base de metal. Me dei o trabalho de parar e ver o valor, R$259,00. Acorda consumidor Brasileiro, estas empresas nos enganam o tempo todo. Olhem a diferença de valores. Qual empresa cobra o dobro ou o triplo pelo mesmo produto somente pela cor? Só o Kabum mesmo. E não se enganem com os preços deles pois vários produtos vendidos por eles, mesmo com desconto chega a ser mais caro, fora o frete que eles cobram. Fujam desta loja, opções não faltam nas grandes cidades e na internet, pesquisem. Não se atirem. E não me venham com o papo de impostos, corona, dólar e blablaba. Amigo consumidor, pare e pense, se uma loja de cidade grande que compra poucas unidades e vende a mesma cadeira por metade do valor do kabum e se for comparada com a cor verde, 3 vezes e meia, vocês realmente acham que o Kabum que compra milhares de cadeiras deste mesmo modelo paga mais caro pela mesma cadeira? Enquanto nós brasileiros formos trouxas de pagar o valor que estas lojas nos cobram por produtos de qualidade duvidosa sempre seremos reféns destes empresários gananciosos que somente visam o lucro incessantemente, mas no momento que nós todos pararmos de pagar por produtos de péssima qualidade eles nunca mais vão fazer este tipo de coisa. Pena que não dá para postar aqui no RA vídeos pois eu iria postar com maior prazer eu desmanchando a cadeira com espuma de alta qualidade deles e mostrando o quanto somos enganados por esta empresa mesquinha e gananciosa ao tentar enganar os consumidores ao vender uma cadeira de não mais de R$300,00 por quase R$900,00. Faço um desafio ao Kabum, provem através de nota fiscal de compra que vocês adquirem por uma fortuna esta cadeira Snow verde para poder justificar a revenda a tal preço esta cadeira de R$894,70 e se provarem eu venho aqui no RA e pesso desculpas para vocês e se vocês pagam realmente um valor super alto somente pela cor o setor de compras de vocês é muito incompetente pois jamais irão vender a mesma cadeira por quase 4 vezes o valor da cor branca por exemplo somente por ser verde. Tá lançado o desafio. Grato pela atenção. | D30: Não | E30: 99 | F30: =combined_output_id__3[[#This Row],[y_pred]] -> Não | G30: =IF(combined_output_id__3[[#This Row],[y_pred]]=combined_output_id__3[[#This Row],[Coluna1]],1,0) -> 1
A31: 29 | B31: 133517787 | C31: numero do pedido : 26648793<br /><br />Fui enganado por esta empresa, que me vendeu um webcam fora de estoque e havia outros 2 produtos, fora a divergência de informação entre as atendentes <br />fica o repúdio total sobre o sistema de vocês tratarem as mercadorias, melhorem antes de vender pois isso é ridiculo 15 dias esperando um produto para trabalho, <br />arrependimento demais comprar com vocês.<br />me informaram que iriam ver a possibilidade de enviarem outro produto, SEM CONFIRMAÇÃO <br />espero que resolvam pois eu quero os 3 produtos e não esperar até dia 30/11 sendo que posso receber agora me poupem | D31: blackfriday | E31: 99 | F31: Não | G31: =IF(combined_output_id__3[[#This Row],[y_pred]]=combined_output_id__3[[#This Row],[Coluna1]],1,0) -> 0
A32: 30 | B32: 133533681 | C32: Além de cancelarem minha compra, não estornaram, então não tenho mais limite pra fazer nenhuma outra compra na Black Friday.<br /><br />Me senti completamente lesado, sem contar com todo o prejuízo que vou ter pq não posso mais aproveitar promoção alguma.<br /><br />Fiz questão de vir aqui reclamar, e vou fazer questão de falar mal da empresa pra todo mundo que conheço.<br /><br />Tô puto de raiva.<br />Vou ter q esperar mais 1 ano pra montar 1 pc de novo. Que merda!<br /><br />Essa empresa é uma piada!! | D32: Não | E32: 95 | F32: =combined_output_id__3[[#This Row],[y_pred]] -> Não | G32: =IF(combined_output_id__3[[#This Row],[y_pred]]=combined_output_id__3[[#This Row],[Coluna1]],1,0) -> 1
A33: 31 | B33: 133481351 | C33: Fiz um pedido (#26753044), que até chegou antes do prazo, mas um dos produtos (Apoio para Pés Husky Technologies 100), veio quebrado dentro da embalagem, que aparentemente estava intacta, minutos após a entrega, percebendo a avaria, entrei em contato com a KaBuM! pelo chat, e me instruíram, pelo próprio site mesmo, a abrir um protocolo (#2512713211122) , coisa que eu fiz prontamente, com fotos, tanto do produto, como da embalagem do produto, e aguardei.<br /><br />Depois de alguns dias, recebi um e-mail da KaBuM!, pedindo mais fotos, mas agora da embalagem grande que vieram todos os produtos, porém, está que era muito grande, eu já havia descartado, e sinceramente não achei que havia necessidade de guardar, pois em nenhum momento do passo-a-passo isso ficou mencionado.<br /><br />Entrei novamente em contato com a KaBuM!, pelo chat mesmo, pois pelo telefone (19 2114.4444) que o site fornece, já entra a chamada que o telefone está programado para não receber ligações, mas confesso que este apenas tentei sem muito esforço, porque o chat geralmente atende rápido, mesmo se mostrando ineficiente, já que toda resposta é &quot;aguarde o recebimento de um e-mail, porque vamos passar pro setor responsável&quot;.<br /><br />Bom, aguardei mais alguns dias, e como não obtive nenhuma resposta, resolvi novamente entrar em contato com o Chat, que me atendeu prontamente, e me informou que meu pedido de garantia, havia sido recusado, pois não conseguiram comprovar a avaria, como tudo na vida parece que você precisa por o pé na mesa pra dar certo, resolvei abrir uma reclamação aqui.<br /><br />Aguardo um posicionamento, porque eu tenho a sensação que estou em um looping burocrático sem o poder de provar nada. | D33: Não | E33: 99 | F33: =combined_output_id__3[[#This Row],[y_pred]] -> Não | G33: =IF(combined_output_id__3[[#This Row],[y_pred]]=combined_output_id__3[[#This Row],[Coluna1]],1,0) -> 1
A34: 32 | B34: 133552887 | C34: Fiz um pedido hoje logo depois quis cancelar pois o protudo não tem garantia,alegaram que o priduto já tinha sido enviado e não podiam cancelar,só que no aplicativo ainda estava em sepaçao,espero devolver e ter o reembolso. | D34: Não | E34: 51 | F34: blackfriday | G34: =IF(combined_output_id__3[[#This Row],[y_pred]]=combined_output_id__3[[#This Row],[Coluna1]],1,0) -> 0
A35: 33 | B35: 133571445 | C35: Fiz um pedido de water cooler e uma placa mãe. Número #27039011. Ontem me entregaram somente o water cooler, entrei no site e deu como pedido finalizado e entregue, sendo que o prazo limite de entrega estava 14/12/2021, agora estou sem a placa mãe e um water cooler que não tem onde ser usado. <br />Liguei para a loja e a atendente falou que iria encaminhar para o setor responsável, pedi o número de protocolo do atendimento, falou que não existe isso e que só poderia passar o seu nome e horário de atendimento, atendente Caroline data 26/11/2021 horário 8:39.<br />Resumindo, não recebi meu produto, não tenho opção no site para reclamar no pedido e o atendimento telefônico não me da garantia que vou ser atendido, se não obter resposta aqui iriei no procon. | D35: Não | E35: 79 | F35: =combined_output_id__3[[#This Row],[y_pred]] -> Não | G35: =IF(combined_output_id__3[[#This Row],[y_pred]]=combined_output_id__3[[#This Row],[Coluna1]],1,0) -> 1
A36: 34 | B36: 133524867 | C36: Comprei um headset wireless no dia 19/11/2021, e chegou no dia 23/11/2021. Usei menos de uma hora, desliguei e depois de um tempo o liguei de novo porém nao ligava de jeito nenhum, achei que fosse bateria porem nao carregava e nem dava sinal de vida. Então entrei em contato com a propria fabricante do produto (Corsair), eles me atenderem super rapido, mas me mandaram entrar em contato com a kabum pois a garantia seria com eles... Abri um protocolo referente a garantia do produto e nao obtive nenhuma resposta ate agora, entrei em contato com eles de todas as formas (chat, telefone, email e nas redes sociais) alem da uma demora tremenda só davam a mesma resposta, que o protocolo seria respondido em até 2 dias uteis e diversas vezes nem respondiam.. ate agora estou sem nenhuma resposta, o produto foi caro e essa demora toda para acionar a garantia é desrespeitavel com qualquer um. | D36: Não | E36: 88 | F36: =combined_output_id__3[[#This Row],[y_pred]] -> Não | G36: =IF(combined_output_id__3[[#This Row],[y_pred]]=combined_output_id__3[[#This Row],[Coluna1]],1,0) -> 1
A37: 35 | B37: 133543873 | C37: Pedi uma RTX 2060 hoje a noite, 25 de novembro de 2021 por volta da meia noite, custando 3599 reais, achando que ja estava em desconto na black friday. Hoje a tarde olhei o preço novamente e havia novas ofertas da mesma placa e de outras, liguei para o atendimento da kabum querendo cancelar meu pedido e receber meu dinheiro de volta até amanhã para aproveitar as novas promoções do mesmo site. Eles disseram que não podem cancelar meu pedido e que só poderão enviar o reembolso em 5 dias uteis, ou seja após a black friday. não comprarei mais na Kabum, como é possivel eu fazer um pedido e não poder cancelar no mesmo dia? | D37: blackfriday | E37: 99 | F37: =combined_output_id__3[[#This Row],[y_pred]] -> blackfriday | G37: =IF(combined_output_id__3[[#This Row],[y_pred]]=combined_output_id__3[[#This Row],[Coluna1]],1,0) -> 1
A38: 36 | B38: 133510385 | C38: No dia 24/11 realizei uma compra de uma Smart TV Philips 55, 4K UHD, 3 HDMI, 2 USB, WiFi, Bluetooth, Dolby Atmos - 55PUG7625/78, com cartão de credito para dar de presente para meu pai.<br />No dia 25/11 fui verificar o status da compra e o pedido se encontrava como cancelado, fui procurar o motivo do cancelamento tendo em vista que a compra foi aprovada pelo meu Banco e o fui informado sobre uma divergência nos dados cadastrais. Gostaria de entender pois estou me sentindo como se fosse um trambiqueiro pois os dados do meu cartão de credito são exatamente os mesmos do cadastro no site.<br />Agora o mais legal de tudo é que hoje a TV aumentou quase mil reais caso eu queira comprar.<br />Se olharem pro meu histórico de compras vão ver que sempre estava comprando alguma coisa no site agora podem ter certeza que nunca mais levar um real meu. | D38: Não | E38: 66 | F38: =combined_output_id__3[[#This Row],[y_pred]] -> Não | G38: =IF(combined_output_id__3[[#This Row],[y_pred]]=combined_output_id__3[[#This Row],[Coluna1]],1,0) -> 1
A39: 37 | B39: 133531273 | C39: Fiz uma compra pelo CNPJ de um notebook Lenovo Gaming i3, cancelaram meu pedido alegando &quot;divergência de dados&quot; sendo que os dados estavam todos corretos, e até porque já fiz compras na kabum com os mesmos dados e foram aprovados, provavelmente viram que deixaram a oferta muito barata e resolveram cancelar pra não ter que vender pelo preço que achei. Agora não consigo nem achar mais o produto no site. Quero o cumprimento da oferta que comprei!! | D39: blackfriday | E39: 99 | F39: =combined_output_id__3[[#This Row],[y_pred]] -> blackfriday | G39: =IF(combined_output_id__3[[#This Row],[y_pred]]=combined_output_id__3[[#This Row],[Coluna1]],1,0) -> 1
A40: 38 | B40: 133538031 | C40: Cobranda indevida, comprei 1 notebook na azul, no site dava como compra cancelada pois eu digitei dados do pagamento diferente do correto, tentei novamente. Então no total fiz 2 compras, mas ambas canceladas pela própria kabum. As duas compras foram parceladas e hoje chegou a minha fatura com 1 notebook parcelado e 2 avista. Gostaria de que se retratassem pois não tenho dinheiro para pagar 2 notebooks a vista. | D40: blackfriday | E40: 57 | F40: Não | G40: =IF(combined_output_id__3[[#This Row],[y_pred]]=combined_output_id__3[[#This Row],[Coluna1]],1,0) -> 0
...

Sheet Planilha1
A1: Quem | B1: COD | C1: ID | D1: Texto | E1: É Black?
A2: Alessandra | B2: 80 | C2: 133475387 | D2: Fiz uma pedido no dia 22/11, e as Casas Bahia disse que iria chegar meu produtos dentro de 2 dias u´teis, hj fui pesquisar aonde esta´ meu produto e ele se encontra em Duque de Caxias, decepcionada. | E2: Não
A3: Alessandra | B3: 87 | C3: 133483133 | D3: NESTA DATA, 24/11/2021, POR VOLTA DAS 13:56HS, COMPARECERAM ATE´ A LOJA CASAS BAHIA, LOCALIZADA NA AVENIDA AFONSO PENA, 217, CENTRO, UBERLANDIA/MG, O SR. ALGIMAR TEODORO DA SILVA ACOMPANHADO DO SEU FILHO, O SR. JONATHAN TEODORO DA SILVA, OS QUAIS FICARAM INTERESSADOS EM UMA PROPAGANDA DO ESTABELECIMENTO QUE OFERTAVA UM APARELHO TELEVISOR SMART TV SAMSUNG 70 POLEGADAS CRISTAL 4K AU7700 NO VALOR DE R$5.129,00. O SR. ALGIMAR AINDA COMPROU UM APARELHO CELULAR MOTOROLA MOTO G10 PELO VALOR DE R$1.099,00, TOTALIZANDO A COMPRA EM R$6.300,00. O SR. ALGIMAR SOLICITOU DIVIDIR A COMPRA EM 10 VEZES NO SEU CARTA~O DE CREDITO OUROCARD PLATINUM VISA, CONTUDO, A VENDEDORA JESSICA SULAMITA DISSE QUE SERIA MAIS VANTAJOSO FAZER UM CARTA~O DA LOJA, POIS PODERIAM DIVIDIR A COMPRA EM 24 VEZES SEM JUROS. O SR. ALGIMAR CONCORDOU, AUTORIZANDO O PROCESSO, LIBERANDO UM CREDITO NO VALOR DE R$4.890,00. COMO O VALOR DO CREDITO NA~O COBRIA A COMPRA, O SR. ALGIMAR ENTA~O, OFERECEU PAGAR O APARELHO CELULAR A VISTA E FINANCIAR SOMENTE A TELEVISA~O. A VENDEDORA DISSE QUE MESMO ASSIM, NA~O DARIA O VALOR DA TELEVISA~O, SENDO SOLICITADO UM APORTE R$599,00, O QUAL FOI FEITO PELO SR. ALGIMAR ATRAVE´S DO BRANCO BRADESCO. EM SEGUIDA, A LOJA FEZ O ESTORNO DO VALOR DE R$599,00 ALEGANDO QUE NA~O TERIA COMO EFETUAR O PARCELAMENTO EM 24 VEZES, POIS, TERIAM QUE FAZER OUTRO APORTE NO VALOR DE R$700,00. A VENDEDORA FEZ UMA SIMULAC¸A~O COM O NOVO APORTE DE R$700,00, CONTUDO, MESMO ASSIM, ALEGARAM QUE NA~O CONSEGUIRAM PARCELAR O VALOR DA TELEVISA~O. O SR. ALGIMAR ENTA~O, COMO NA~O FOI ATENDIDO PELA LOJA, SOLICITOU O CANCELAMENTO DO CARTA~O, O QUAL FOI NEGADO PELO GERENTE, QUE DISSE QUE ELE MESMO DEVERIA SOLICITAR O CANCELAMENTO APO´S 15 DIAS. O SR. ALGIMAR NA~O CONCORDOU E DISSE QUE QUERIA SEU CARTA~O CANCELADO, SENDO GERADO UM "UM TERMO DE CANCELAMENTO DE CARTA~O POIS O CLIENTE DESISTIU DEVIDO O LIMITE NA~O ATENDE-LO". O SR. ALGIMAR SOLICITOU O CONTRATO QUE ELE ASSINOU DA PROPOSTA DO CARTA~O, SENDO SETE FOLHAS ASSINADAS, TODAVIA, O GERENTE SE NEGOU, RECORTOU DUAS ASSINATURAS E ENTREGOU PARA O SR. ALGIMAR E MANDOU FOTOS DAS DEMAIS FOLHAS VIA WHATSAPP. DIANTE DISTO FAC¸O A DEVIDA RECLAMAC¸A~O POIS FUI TRATADO DE FORMA DESELEGANTE PELO GERENTE QUE QUANDO CHAMADO POR ESTE RECLAMANTE PARA EXPLICAR O PORQUE DO FATO DE NA~O TER CONSEGUIDO EFETUAR A COMPRA APO´S PERMANECER NA LOJA PELO PERI´ODO DE 3 HORAS, ESTE FOI DESELEGANTE E QUESTIONADO O PORQUE DAQUELE TRATAMENTO ESTE SE MOSTROU NERVOSO E QUIS QUE O RECLAMANTE O AGREDISSE COM PALAVRAS O QUE NA~O FOI FEITO.aTE ESTA DATA TINHA UM ZELO POR ESTE ESTABELECIMENTO MAS PELA EMPRESA ADMITIR PESSOAS COMO ESTE GERENTE PARA TRATAR COM PESSOAS PERDE TODA CREDIBILIDADE. | E3: Blackfriday
A4: Alessandra | B4: 94 | C4: 133516657 | D4: COMPREI UM CONJUNTO DE PANELAS NO SITE CASAS BAHIA, PORE´M AS PANELAS ESTAO TODAS AMASSADAS E O PRODUTO COMPLETAMENTE FRAGIL E DE MAL MATERIAL, ENTREI EM CONTATO COM A EMPRESA E ME DERAM 4 DIAS UTEIS PARA RECEBER UM EMAIL PARA CONFIRMAC¸A~O DE CANCELAMENTO DA COMPRA, NAO RECEBI EMAIL NENHUM NOVAMENTE ENTREI EM CONTATO E PEDIRAM PRA AGUARDAR MAIS 4 DIAS UTEIS, UMA PALHAC¸ADA COM O CONSUMIDOR. DEVE SER RESPEITADO O PRAZO QUE ME INFORMAM PARA A TRATATIVA. FALTA DE RESPEITO POIS LIGUEI DIVERSAS VEZES PEDINDO UM NUMERO DE OUVIDORIA, UNS DESLIGAM NA MINHA CARA E OUTROS FALAM QUE NAO TEM COMO REGISTRAR RECLAMAC¸A~O EM OUVIDORIA !! ABSURDO. QUERO MEU DINHEIRO | E4: Não
A5: Alessandra | B5: 101 | C5: 133464721 | D5: Fiz a compra de um iPhone 11 no site das Casas Bahia e estava previsto para ser entregue hoje, pore´m a transportadora adiou a entrega alegando que na~o havia ningue´m para receber a mercadoria sendo que moro em condomi´nio onde tem porteiro 24h. Tentei entrar em contato com a transportadora para saber e eles na~o atendem, liguei na Casas Bahia e o atendente falou que na~o podia fazer nada. Quero que resolvem logo meu problema! | E5: Não
A6: Alessandra | B6: 108 | C6: 133525885 | D6: No dia 19/11/2021 fiz a compra de um smartphone no site da empresa CasasBahia. Depois do processo de aprovac¸a~o de pagamento do pedido N 299328341, o site CasasBahia da o prazo de entrega ate´ 25/11/2021. A CasasBahia fez a terceirizac¸a~o a entrega pela Loggi. Segundo a Loggi por uma mensagem no WhatsApp o entregador veio com o pedido ate o enderec¸o e fez a entrega, mas nem chamou e na casa tinha gente para receber o pedido. E simplesmente o entregador da Loggi deu o pedido como entregue no dia 24/11/2021 as 20:56h. Colocou o nome "Flavio." Para o recebedor do pedido e ningue´m aqui na casa recebeu o pedido. Ate´ o momento estou tendo um prejui´zo de mais de mil reais e na~o estou tendo o retorno desejado para solucionar o caso. Espero que resolva entre as empresas CasasBahia e Loggi a entrega do produto ou reembolso. A Loggi na~o envia os dados e nem a assinatura do recebedor do produto. Entrega o pedido a qualquer um sem identificac¸a~o e o consumidor que vai ficar no prejui´zo? Espero a soluc¸a~o do caso. | E6: Não
A7: Alessandra | B7: 115 | C7: 133475641 | D7: Estou deste a noite de 23/11 tentando comprar Iphones e notbooks no site da ponto frio, pore´m quando chega o momeno de finalizar a compra na~o aparece o link de pontuar tudo azul. Ja´ falei com atendentes, ja´ liguei, mas ningue´m resolve meu problema. tenho medo de fazer as compras e na~o ter uma garantia de que serei pontuada. No ano passado comprei um colcha~o nesta mesma promoc¸a~o e por na~o ter aparecido o link para pontuar, na~o fui pontuada. todo black friday compro na ponto frio justamente por causa das pontuac¸o~es tudo azul. Parece que esse ano eles esta~o dispostos a perder varias vendas. numero do pedido 300379632 | E7: Blackfriday
A8: Alessandra | B8: 122 | C8: 133462817 | D8: Comprei um ar de janela, no dia 1/11 cujo o prazo de entrega era estourando dia 9/11, apo´s passar 1 dia da data de entrega entrei em contato com a loja via ligac¸a~o e WhatsApp para solicitar o cancelamento, e fiz isso apo´s ver que a minha encomenDa estava parada na transportadora JAdlog desde o dia 5/11. A transportado e´ horri´vel e mal recomendada por aqui tbm. Enfim hoje ja´ estamos no dia 23/11 o o extra insiste em na~o me devolver o meu dinheiro mesmo com o print de que a transportadora na~o vai me entregar. Quero meu estorno o quanto antes. Hoje fiz mais uma solicitac¸a~o de cancelamento o atendente A´lissons as 14:07 me atendeu e as 14:23 disse que havia aberto o meu protocolo de cancelamento, mas ao verificar o protocolo fui informada de que o mesmo na~o existe. Quando tento cancelar pelo aplicativo o extra na~o permite. | E8: Não
A9: Alessandra | B9: 129 | C9: 133466135 | D9: Comprei o iPhone no fim de outubro, apresentou problemas na bateria antes dos 7 dias da compra e estou ate´ agora tentando resolver. Toda hora mudam a data da coleta. Preciso do telefone a trabalho!!! Estou quase entrando com um processo. | E9: Não
A10: Alessandra | B10: 136 | C10: 133484997 | D10: Boa noite Preciso recuperar minha senha mas perdi meu email cadastrado e na~o estou conseguindo Gostaria de fazer compra. Fico no aguardo, att | E10: Não
A11: Alessandra | B11: 143 | C11: 133524353 | D11: Recebi Hoje o produto e o produto veio com defeitos ele nao carrega desligado colocar para carregar desligado ele Liga sozinho a bateria nao Segura carga exemplo selular ESTA com 30% em 1 Segundo ele ja descarregar ele com 7 porcento em 2 Segundo s chegou a 1 porcento e descarregou gostaria que vcs fezessem a troca do produto mais rapido possivel | E11: Não
A12: Alessandra | B12: 150 | C12: 133457473 | D12: Boa tarde. Efetuei a compra de um produto(pedido 297479947) no dia 11/11/21, atrave´s do marketplace das Casas Bahia, cujo o produto e´ vendido pela loja Vills Parfum. A data de entrega do produto segundo informac¸o~es do aplicativo das Casas Bahia seria dia 17/11/21, pore´m o produto na~o foi entregue, enta~o realizei contato atrave´s do whatsapp no dia 18/11/21(protocolo 211118-000277) e fui informado que o retorno ocorreria em ate´ 4 dias u´teis o que na~o aconteceu. Tambe´m realizei contato dia 23/11 com a Vills Parfum deixei meu contato e na~o recebi retorno. | E12: Não
A13: Alessandra | B13: 157 | C13: 133521379 | D13: Dia 21/11 fiz a compra de uma escova secadora pelo app da loja a qual forma de pagamento foi via pix no mesmo momento da compra ate´ a presente data os status na~o mudou apesar das inu´meras tentativas de resolver o problema a empresa na~o altera o status tao pouco me devolve o valor. Sempre o mesmo abri um pedido de aprovac¸a~o do pagamento com urge^ncia 24hs seu problema sera´ resolvido e nisso ja´ va~o 4 dias. | E13: Não
... A210: Ymair | B210: 280 | C210: 133561325 | D210: As casas Bahia cancelaram um compra de uma ferramento para uso na minha empresa sem minha autorizac¸a~o, ao ligar so telefone deles e pelo whattapp me informaram que o fornecedor do produto ficou sem estoque e sem previc¸a~o de reposic¸a~o, deixei de compra em outro site para compra com eles e agora estou precisando a ferramenta sem na~o estou querendo reembolso que o produto que comprei que por sinal receberam na hora por pix, aogra cancelaram e ainda estou me falando que vao vou qual o dia vai ser realizaro essa devoluc¸a~o, nao quero reenboldo quero que envio a mercadora compra vou siminar como manda a a lei do consulmido. Nu´mero do pedido 299714366 Data da compra 21/11/2021 Valor total R$ 451,37 Tipo de entrega Normal conversar pelo whatapp [09:17, 25/11/2021] Casas Bahia Atendimento: Carlos, seu produto ainda na~o foi repassado ao transportador. Assim que ele for repassado, voce^ sera´ notificado via e-mail e tambe´m recebera´ o co´digo de rastreio para acompanhar a entrega. Data Prometida de Entrega: 07/12/2021 [09:18, 25/11/2021] Cloud Monitoramento Priva: me informaram pelo telefone que o produtos nao esta mais em estoque na loja parceira [09:18, 25/11/2021] Casas Bahia Atendimento: Deixa eu verificar em sistema, so´ um momento. [09:22, 25/11/2021] Casas Bahia Atendimento: Carlos, verifiquei em sistema que realmente foi registrado que o produto ficou indisponi´vel em estoque: "23/11/2021 15:40 - Elo'undefined - Caros, Nosso lojista teve um imprevisto com relac¸a~o ao estoque do produto e na~o temos previsa~o para a reposic¸a~o do item. Por gentileza efetuar o cancelamento" Pore´m, ontem, dia 25/11, foi aberto um chamado para que verifiquem se e´ possi´vel encaminhar um produto similar. O prazo ma´ximo que nosso time leva para entrar em contato com vc por e-mail ou telefone e´ de 04 dias u´teis. Voce^ deseja aguardar o retorno do setor responsa´vel confirmando se conseguira~o enviar um produto similar, ou prefere prosseguir com o cancelamento? [09:24, 25/11/2021] Cloud Monitoramento Priva: Vou aguardar, na~o quero cancelar quero o produto [09:26, 25/11/2021] Casas Bahia Atendimento: Ta´ bem. | E210: Não
